<?xml version="1.0" ?>
<!-- =================================================================================== -->
<!-- |    This document was autogenerated by xacro from ur5_robot.urdf.xacro           | -->
<!-- |    EDITING THIS FILE BY HAND IS NOT RECOMMENDED                                 | -->
<!-- =================================================================================== -->
<robot name="ur5" xmlns:xacro="http://ros.org/wiki/xacro">
  <!-- measured from model -->
  <!--property name="shoulder_height" value="0.089159" /-->
  <!--property name="shoulder_offset" value="0.13585" /-->
  <!-- shoulder_offset - elbow_offset + wrist_1_length = 0.10915 -->
  <!--property name="upper_arm_length" value="0.42500" /-->
  <!--property name="elbow_offset" value="0.1197" /-->
  <!-- CAD measured -->
  <!--property name="forearm_length" value="0.39225" /-->
  <!--property name="wrist_1_length" value="0.093" /-->
  <!-- CAD measured -->
  <!--property name="wrist_2_length" value="0.09465" /-->
  <!-- In CAD this distance is 0.930, but in the spec it is 0.09465 -->
  <!--property name="wrist_3_length" value="0.0823" /-->
  <!-- manually measured -->
  <!-- Arm Links -->
  <link name="base_link">
    <visual name="base_link_visual">
      <geometry>
        <mesh filename="meshes/ur5/visual/base.dae"/>
      </geometry>
    </visual>
    <collision name="base_link_collision">
      <geometry>
        <mesh filename="meshes/ur5/collision/base.stl"/>
      </geometry>
    </collision>
  </link>

  <link name="shoulder_link">
    <visual name="shoulder_link_visual">
      <geometry>
        <mesh filename="meshes/ur5/visual/shoulder.dae"/>
      </geometry>
    </visual>
    <collision name="shoulder_link_collision">
      <geometry>
        <mesh filename="meshes/ur5/collision/shoulder.stl"/>
      </geometry>
    </collision>
  </link>

  <link name="upper_arm_link">
    <visual name="upper_arm_link_visual">
      <geometry>
        <mesh filename="meshes/ur5/visual/upperarm.dae"/>
      </geometry>
    </visual>
    <collision name="upper_arm_link_collision">
      <geometry>
        <mesh filename="meshes/ur5/collision/upperarm.stl"/>
      </geometry>
    </collision>
  </link>

  <link name="forearm_link">
    <visual name="forearm_link_visual">
      <geometry>
        <mesh filename="meshes/ur5/visual/forearm.dae"/>
      </geometry>
    </visual>
    <collision name="forearm_link_collision">
      <geometry>
        <mesh filename="meshes/ur5/collision/forearm.stl"/>
      </geometry>
    </collision>
  </link>

  <link name="wrist_1_link">
    <visual name="wrist_1_link_visual">
      <geometry>
        <mesh filename="meshes/ur5/visual/wrist1.dae"/>
      </geometry>
    </visual>
    <collision name="wrist_1_link_collision">
      <geometry>
        <mesh filename="meshes/ur5/collision/wrist1.stl"/>
      </geometry>
    </collision>
  </link>

  <link name="wrist_2_link">
    <visual name="wrist_2_link_visual">
      <geometry>
        <mesh filename="meshes/ur5/visual/wrist2.dae"/>
      </geometry>
    </visual>
    <collision name="wrist_2_link_collision">
      <geometry>
        <mesh filename="meshes/ur5/collision/wrist2.stl"/>
      </geometry>
    </collision>
  </link>

  <link name="wrist_3_link">
    <visual name="wrist_3_link_visual">
      <geometry>
        <mesh filename="meshes/ur5/visual/wrist3.dae"/>
      </geometry>
    </visual>
    <collision name="wrist_3_link_collision">
      <geometry>
        <mesh filename="meshes/ur5/collision/wrist3.stl"/>
      </geometry>
    </collision>
  </link>


  <!-- Arm Joints -->
  <joint name="shoulder_pan_joint" type="revolute">
    <parent link="base_link"/>
    <child link="shoulder_link"/>
    <origin xyz="0 0 0.089159" rpy="0 0 0"/>
    <axis xyz="0 0 1"/>
    <limit lower="-6.28319" upper="6.28319" effort="150.0" velocity="3.15"/>
  </joint>

  <joint name="shoulder_lift_joint" type="revolute">
    <parent link="shoulder_link"/>
    <child link="upper_arm_link"/>
    <origin xyz="0 0.13585 0" rpy="0 0 0"/>
    <axis xyz="0 1 0"/>
    <limit lower="-6.28319" upper="6.28319" effort="150.0" velocity="3.15"/>
  </joint>

  <joint name="elbow_joint" type="revolute">
    <parent link="upper_arm_link"/>
    <child link="forearm_link"/>
    <origin xyz="0 -0.1197 0.425" rpy="0 0 0"/>
    <axis xyz="0 1 0"/>
    <limit lower="-6.28319" upper="6.28319" effort="150.0" velocity="3.15"/>
  </joint>

  <joint name="wrist_1_joint" type="revolute">
    <parent link="forearm_link"/>
    <child link="wrist_1_link"/>
    <origin xyz="0 0 0.39225" rpy="0 0 0"/>
    <axis xyz="0 1 0"/>
    <limit lower="-6.28319" upper="6.28319" effort="28.0" velocity="3.2"/>
  </joint>

  <joint name="wrist_2_joint" type="revolute">
    <parent link="wrist_1_link"/>
    <child link="wrist_2_link"/>
    <origin xyz="0 0.093 0" rpy="0 0 0"/>
    <axis xyz="0 0 1"/>
    <limit lower="-6.28319" upper="6.28319" effort="28.0" velocity="3.2"/>
  </joint>

  <joint name="wrist_3_joint" type="revolute">
    <parent link="wrist_2_link"/>
    <child link="wrist_3_link"/>
    <origin xyz="0 0 0.09465" rpy="0 0 0"/>
    <axis xyz="0 1 0"/>
    <limit lower="-6.28319" upper="6.28319" effort="28.0" velocity="3.2"/>
  </joint>


  <!-- Arm-Hand Fixed Joint -->

  <joint name="ee_fixed_joint" type="fixed"> 
    <parent link="wrist_3_link"/>
    <child link="ee_link"/>
    <axis xyz="0 0 1"/>
    <origin rpy="0 0 3.141592653589793" xyz="0.0 0.0823 0.0"/> 
  </joint>

  <link name="ee_link">
    <inertial>
      <origin xyz="8.625E-08 -4.6583E-06 0.03145" rpy="0 0 0" />
      <mass value="0.22652" />
      <inertia ixx="0.00020005" ixy="-4.2442E-10" ixz="-2.9069E-10" iyy="0.00017832" iyz="-3.4402E-08" izz="0.00013478" />
    </inertial>
    <visual>
      <origin xyz="0 0 0" rpy="0 0 0" />
      <geometry>
        <mesh filename="meshes/robotiq_2f_140/visual/robotiq_arg2f_base_link.stl" />
      </geometry>
      <material name="">
        <color rgba="0.9 0.1 0.1 1" />
      </material>
    </visual>
    <collision>
      <origin xyz="0.0 0.0 0.0" rpy="1.57079632678995 0 0" />
      <geometry>
        <mesh filename="meshes/robotiq_2f_140/collision/robotiq_arg2f_base_link.stl" />
      </geometry>
    </collision>
  </link>

  <link name="left_inner_knuckle">
    <inertial>
      <origin xyz="0.000123011831763771 0.0507850843201817 0.00103968640075166" rpy="0 0 0" />
      <mass value="0.0271177346495152" />
      <inertia
          ixx="2.61910379223783E-05"
          ixy="-2.43616858946494E-07"
          ixz="-6.37789906117123E-09"
          iyy="2.8270243746167E-06"
          iyz="-5.37200748039765E-07"
          izz="2.83695868220296E-05" />
    </inertial>
    <visual>
      <origin xyz="0 0 0" rpy="0 0 0" />
      <geometry>
        <mesh filename="meshes/robotiq_2f_140/visual/robotiq_arg2f_140_inner_knuckle.stl" />
      </geometry>
      <material name="">
        <color rgba="0.1 0.1 0.1 1" />
      </material>
    </visual>
    <collision>
      <origin xyz="0 0 -0.025" rpy="1.57079632678995 0 0" />
      <geometry>
        <mesh filename="meshes/robotiq_2f_140/collision/robotiq_arg2f_140_inner_knuckle.stl" />
      </geometry>
    </collision>
  </link> 

  <link name="right_inner_knuckle">
    <inertial>
      <origin xyz="0.000123011831763771 0.0507850843201817 0.00103968640075166" rpy="0 0 0" />
      <mass value="0.0271177346495152" />
      <inertia
          ixx="2.61910379223783E-05"
          ixy="-2.43616858946494E-07"
          ixz="-6.37789906117123E-09"
          iyy="2.8270243746167E-06"
          iyz="-5.37200748039765E-07"
          izz="2.83695868220296E-05" />
    </inertial>
    <visual>
      <origin xyz="0 0 0" rpy="0 0 0" />
      <geometry>
        <mesh filename="meshes/robotiq_2f_140/visual/robotiq_arg2f_140_inner_knuckle.stl" />
      </geometry>
      <material name="">
        <color rgba="0.1 0.1 0.1 1" />
      </material>
    </visual>
    <collision>
      <origin xyz="0 0 -0.025" rpy="1.57079632678995 0 0" />
      <geometry>
        <mesh filename="meshes/robotiq_2f_140/collision/robotiq_arg2f_140_inner_knuckle.stl" />
      </geometry>
    </collision>
  </link>

  <joint name="left_inner_knuckle_joint" type="revolute">
    <origin xyz="0 -0.06142 -0.0127" rpy="2.2957963267948965 0 0" />
    <parent link="ee_link" />
    <child link="left_inner_knuckle" />
    <axis xyz="1 0 0" />
    <limit lower="-0.5757" upper="0.5757" velocity="2.0" effort="1000" />
    <mimic joint="finger_joint" multiplier="-1" offset="0" />
  </joint>

  <joint name="right_inner_knuckle_joint" type="revolute">
    <origin xyz="0 -0.06142 0.0127" rpy="-2.2957963267948965 3.141592653589793 -3.141592653589793" />
    <parent link="ee_link" />
    <child link="right_inner_knuckle" />
    <axis xyz="1 0 0" />
    <limit lower="-0.5757" upper="0.5757" velocity="2.0" effort="1000" />
    <mimic joint="finger_joint" multiplier="1" offset="0" />
  </joint> 

  <link name="left_outer_knuckle">
    <inertial>
      <origin xyz="-0.000200000000003065 0.0199435877845359 0.0292245259211331" rpy="0 0 0" />
      <mass value="0.00853198276973456" />
      <inertia
          ixx="2.89328108496468E-06"
          ixy="-1.57935047237397E-19"
          ixz="-1.93980378593255E-19"
          iyy="1.86719750325683E-06"
          iyz="-1.21858577871576E-06"
          izz="1.21905238907251E-06" />
    </inertial>
    <visual>
      <origin xyz="0 0 0" rpy="0 0 0" />
      <geometry>
        <mesh filename="meshes/robotiq_2f_140/visual/robotiq_arg2f_140_outer_knuckle.stl" />
      </geometry>
      <material name="">
        <color rgba="0.792156862745098 0.819607843137255 0.933333333333333 1" />
      </material>
    </visual>
    <collision>
      <origin xyz="0 0 0" rpy="1.57079632678995 0 0" />
      <geometry>
        <mesh filename="meshes/robotiq_2f_140/collision/robotiq_arg2f_140_outer_knuckle.stl" />
      </geometry>
    </collision>
  </link>

  <link name="right_outer_knuckle">
    <inertial>
      <origin xyz="-0.000200000000003065 0.0199435877845359 0.0292245259211331" rpy="0 0 0" />
      <mass value="0.00853198276973456" />
      <inertia
          ixx="2.89328108496468E-06"
          ixy="-1.57935047237397E-19"
          ixz="-1.93980378593255E-19"
          iyy="1.86719750325683E-06"
          iyz="-1.21858577871576E-06"
          izz="1.21905238907251E-06" />
    </inertial>
    <visual>
      <origin xyz="0 0 0" rpy="0 0 0" />
      <geometry>
        <mesh filename="meshes/robotiq_2f_140/visual/robotiq_arg2f_140_outer_knuckle.stl" />
      </geometry>
      <material name="">
        <color rgba="0.792156862745098 0.819607843137255 0.933333333333333 1" />
      </material>
    </visual>
    <collision>
      <origin xyz="0 0 0" rpy="1.57079632678995 0 0" />
      <geometry>
        <mesh filename="meshes/robotiq_2f_140/collision/robotiq_arg2f_140_outer_knuckle.stl" />
      </geometry>
    </collision>
  </link>

  <joint name="finger_joint" type="revolute">
    <origin xyz="0 -0.054905 -0.030601" rpy="2.2957963267948965 0 0" />
    <parent link="ee_link" />
    <child link="left_outer_knuckle" />
    <axis xyz="-1 0 0" />
    <limit lower="-0.725" upper="0.725" velocity="2.0" effort="1000" />
  </joint>

  <joint name="right_outer_knuckle_joint" type="revolute">
    <origin xyz="0 -0.054905 0.030601" rpy="-0.8457 0 -3.141592653589793" />
    <parent link="ee_link" />
    <child link="right_outer_knuckle" />
    <axis xyz="1 0 0" />
    <limit lower="-0.725" upper="0.725" velocity="2.0" effort="1000" />
    <mimic joint="finger_joint" multiplier="-1" offset="0" />
  </joint>

  <link name="left_outer_finger">
    <inertial>
      <origin xyz="0.00030115855001899 0.0373907951953854 -0.0208027427000385" rpy="0 0 0" />
      <mass value="0.022614240507152" />
      <inertia
          ixx="1.52518312458174E-05"
          ixy="9.76583423954399E-10"
          ixz="-5.43838577022588E-10"
          iyy="6.17694243867776E-06"
          iyz="6.78636130740228E-06"
          izz="1.16494917907219E-05" />
    </inertial>
    <visual>
      <origin xyz="0 0 0" rpy="0 0 0" />
      <geometry>
        <mesh filename="meshes/robotiq_2f_140/visual/robotiq_arg2f_140_outer_finger.stl" />
      </geometry>
      <material name="">
        <color rgba="0.1 0.1 0.1 1" />
      </material>
    </visual>
    <collision>
      <origin xyz="0 0 0" rpy="1.57079632678995 0 0" />
      <geometry>
        <mesh filename="meshes/robotiq_2f_140/collision/robotiq_arg2f_140_outer_finger.stl" />
      </geometry>
    </collision>
  </link>

  <link name="right_outer_finger">
    <inertial>
      <origin xyz="0.00030115855001899 0.0373907951953854 -0.0208027427000385" rpy="0 0 0" />
      <mass value="0.022614240507152" />
      <inertia
          ixx="1.52518312458174E-05"
          ixy="9.76583423954399E-10"
          ixz="-5.43838577022588E-10"
          iyy="6.17694243867776E-06"
          iyz="6.78636130740228E-06"
          izz="1.16494917907219E-05" />
    </inertial>
    <visual>
      <origin xyz="0 0 0" rpy="0 0 0" />
      <geometry>
        <mesh filename="meshes/robotiq_2f_140/visual/robotiq_arg2f_140_outer_finger.stl" />
      </geometry>
      <material name="">
        <color rgba="0.1 0.1 0.1 1" />
      </material>
    </visual>
    <collision>
      <origin xyz="0 0 0" rpy="1.57079632678995 0 0" />
      <geometry>
        <mesh filename="meshes/robotiq_2f_140/collision/robotiq_arg2f_140_outer_finger.stl" />
      </geometry>
    </collision>
  </link>

  <joint name="left_outer_finger_joint" type="fixed">
    <origin xyz="0 -0.0260018192872234 0.01821998610742" rpy="0 0 0" />
    <parent link="left_outer_knuckle" />
    <child link="left_outer_finger" />
    <axis xyz="1 0 0" />
  </joint>

  <joint name="right_outer_finger_joint" type="fixed">
    <origin xyz="0 -0.0260018192872234 0.01821998610742" rpy="0 0 0" />
    <parent link="right_outer_knuckle" />
    <child link="right_outer_finger" />
    <axis xyz="1 0 0" />
  </joint>

  <link name="left_inner_finger">
    <inertial>
      <origin xyz="0.000299999999999317 0.0160078233491243 -0.0136945669206257" rpy="0 0 0" />
      <mass value="0.0104003125914103" />
      <inertia
          ixx="2.71909453810972E-06"
          ixy="1.35402465472579E-21"
          ixz="-7.1817349065269E-22"
          iyy="7.69100314106116E-07"
          iyz="6.74715432769696E-07"
          izz="2.30315190420171E-06" />
    </inertial>
    <visual>
      <origin xyz="0 0 0" rpy="0 0 0" />
      <geometry>
        <mesh filename="meshes/robotiq_2f_140/visual/robotiq_arg2f_140_inner_finger.stl" />
      </geometry>
      <material name="">
        <color rgba="0.1 0.1 0.1 1" />
      </material>
    </visual>
    <collision>
      <origin xyz="0 0 0" rpy="1.57079632678995 0 0" />
      <geometry>
        <mesh filename="meshes/robotiq_2f_140/collision/robotiq_arg2f_140_inner_finger.stl" />
      </geometry>
    </collision>
  </link>

  <link name="right_inner_finger">
    <inertial>
      <origin xyz="0.000299999999999317 0.0160078233491243 -0.0136945669206257" rpy="0 0 0" />
      <mass value="0.0104003125914103" />
      <inertia
          ixx="2.71909453810972E-06"
          ixy="1.35402465472579E-21"
          ixz="-7.1817349065269E-22"
          iyy="7.69100314106116E-07"
          iyz="6.74715432769696E-07"
          izz="2.30315190420171E-06" />
    </inertial>
    <visual>
      <origin xyz="0 0 0" rpy="0 0 0" />
      <geometry>
        <mesh filename="meshes/robotiq_2f_140/visual/robotiq_arg2f_140_inner_finger.stl" />
      </geometry>
      <material name="">
        <color rgba="0.1 0.1 0.1 1" />
      </material>
    </visual>
    <collision>
      <origin xyz="0 0 0" rpy="1.57079632678995 0 0" />
      <geometry>
        <mesh filename="meshes/robotiq_2f_140/collision/robotiq_arg2f_140_inner_finger.stl" />
      </geometry>
    </collision>
  </link>

  <joint name="left_inner_finger_joint" type="revolute">
    <origin xyz="0 0.0282203446692936 0.0817554015893473" rpy="-0.725 0 0" />
    <parent link="left_outer_finger" />
    <child link="left_inner_finger" />
    <axis xyz="1 0 0" />
    <limit lower="-0.5757" upper="0.5757" velocity="2.0" effort="1000" />
    <mimic joint="finger_joint" multiplier="1" offset="0" />
  </joint>

  <joint name="right_inner_finger_joint" type="revolute">
    <origin xyz="0 0.0282203446692936 0.0817554015893473" rpy="-0.725 0 0" />
    <parent link="right_outer_finger" />
    <child link="right_inner_finger" />
    <axis xyz="1 0 0" />
    <limit lower="-0.5757" upper="0.5757" velocity="2.0" effort="1000" />
    <mimic joint="finger_joint" multiplier="1" offset="0" />
  </joint>

  <link
    name="left_gelsight_connector">
    <inertial>
      <origin
        xyz="-0.157663212592476 -0.000124171196531324 0.120438138444188"
        rpy="0 0 0" />
      <mass
        value="0.0221225285478857" />
      <inertia
        ixx="1.07229927214735E-05"
        ixy="-4.04103873091654E-21"
        ixz="2.15379317805456E-06"
        iyy="9.94855881736576E-06"
        iyz="6.62592000000011E-08"
        izz="3.68644003164057E-06" />
    </inertial>
    <visual>
      <origin
        xyz="0 0 0"
        rpy="0 0 0" />
      <geometry>
        <mesh
          filename="meshes/gelsight_robotiq_connector/visual/gelsight_robotiq.STL" />
      </geometry>
      <material
        name="">
        <color
          rgba="1 1 1 1" />
      </material>
    </visual>
    <collision>
      <origin
        xyz="0.0 0.0 0.0"
        rpy="1.5707963267899 0 0" />
      <geometry>
        <mesh       
          filename="meshes/gelsight_robotiq_connector/collision/gelsight_robotiq.STL" />
      </geometry>
    </collision>
  </link>

  <link
    name="right_gelsight_connector">
    <inertial>
      <origin
        xyz="-0.157663212592476 -0.000124171196531324 0.120438138444188"
        rpy="0 0 0" />
      <mass
        value="0.0221225285478857" />
      <inertia
        ixx="1.07229927214735E-05"
        ixy="-4.04103873091654E-21"
        ixz="2.15379317805456E-06"
        iyy="9.94855881736576E-06"
        iyz="6.62592000000011E-08"
        izz="3.68644003164057E-06" />
    </inertial>
    <visual>
      <origin
        xyz="0 0 0"
        rpy="0 0 0" />
      <geometry>
        <mesh
          filename="meshes/gelsight_robotiq_connector/visual/gelsight_robotiq.STL" />
      </geometry>
      <material
        name="">
        <color
          rgba="1 1 1 1" />
      </material>
    </visual>
    <collision>
      <origin
        xyz="0 0 0"
        rpy="1.5707963267899 0 0" />
      <geometry>
        <mesh
          filename="meshes/gelsight_robotiq_connector/collision/gelsight_robotiq.STL" />
      </geometry>
    </collision>
  </link>

  <joint name="left_gelsight_connector" type="fixed">
    <origin xyz="0 0.1768 -0.0745" rpy="-1.5707963267899 0 1.5707963267899" />
    <parent link="left_inner_finger" />
    <child link="left_gelsight_connector" />
    <axis xyz="0 0 1" />
  </joint>
  <joint name="right_gelsight_connector" type="fixed">
    <origin xyz="0 0.1768 -0.0745" rpy="-1.5707963267899 0 1.5707963267899" />
    <parent link="right_inner_finger" />
    <child link="right_gelsight_connector" />
    <axis xyz="0 0 1" />
  </joint>

  <link
    name="left_gelsight_mini">
    <inertial>
      <origin
        xyz="-0.109892156902594 0.041534939290952 0.150431592177723"
        rpy="0 0 0" />
      <mass
        value="0.00521824808646558" />
      <inertia
        ixx="7.98413040723359E-07"
        ixy="-4.47118903495661E-10"
        ixz="-7.80447946148685E-10"
        iyy="5.68310810488415E-07"
        iyz="7.93106143462849E-10"
        izz="4.0985124041434E-07" />
    </inertial>
    <visual>
      <origin
        xyz="0 0 0"
        rpy="0 0 0" />
      <geometry>
        <mesh
          filename="meshes/gelsight_mini/visual/base_link.STL" />
      </geometry>
      <material
        name="">
        <color
          rgba="1 1 1 1" />
      </material>
    </visual>
    <collision>
      <origin
        xyz="0 0 0"
        rpy="1.5707963267899 0 0" />
      <geometry>
        <mesh
          filename="meshes/gelsight_mini/collision/base_link.STL" />
      </geometry>
    </collision>
  </link>

  <link
    name="right_gelsight_mini">
    <inertial>
      <origin
        xyz="-0.109892156902594 0.041534939290952 0.150431592177723"
        rpy="0 0 0" />
      <mass
        value="0.00521824808646558" />
      <inertia
        ixx="7.98413040723359E-07"
        ixy="-4.47118903495661E-10"
        ixz="-7.80447946148685E-10"
        iyy="5.68310810488415E-07"
        iyz="7.93106143462849E-10"
        izz="4.0985124041434E-07" />
    </inertial>
    <visual>
      <origin
        xyz="0 0 0"
        rpy="0 0 0" />
      <geometry>
        <mesh
          filename="meshes/gelsight_mini/visual/base_link.STL" />
      </geometry>
      <material
        name="">
        <color
          rgba="1 1 1 1" />
      </material>
    </visual>
    <collision>
      <origin
        xyz="0 0 0"
        rpy="1.5707963267899 0 0" />
      <geometry>
        <mesh
          filename="meshes/gelsight_mini/collision/base_link.STL" />
      </geometry>
    </collision>
  </link>

    <link name="left_box">   
    <!-- <visual>
      <origin xyz="0 0 0.002" rpy="0 0 0"/>
      <geometry>
          <box size="0.03 0.025 0.004"/>
      </geometry>
    </visual>  -->

    <collision>
        <origin xyz="0 0 0.00" rpy="0 0 0"/>
        <geometry>
          <box size="0.026 0.022 0.009"/>
        </geometry>
    </collision>
  </link>

  <link name="right_box">   
    <!-- <visual>
      <origin xyz="0 0 0.002" rpy="0 0 0"/>
      <geometry>
          <box size="0.03 0.025 0.004"/>
      </geometry>
    </visual>  -->

    <collision>
        <origin xyz="0 0 0.00" rpy="0 0 0"/>
        <geometry>
          <box size="0.026 0.022 0.009"/>
        </geometry>
    </collision>
  </link>


	<joint name = "left_attach" type = "fixed">
		<origin xyz = "0.0 -0.02 0.0 " rpy = "1.5707963267948966 0 0"/>
		<parent link = "left_gelsight_mini"/>
		<child link = "left_box"/>  
	</joint>

	<joint name = "right_attach" type = "fixed">
		<origin xyz = "0.0 -0.02 0.0" rpy = "1.5707963267948966 0 0"/>
		<parent link = "right_gelsight_mini"/>
		<child link = "right_box"/>
	</joint>


  <joint name="left_gelsight" type="fixed">
    <origin xyz="-0.1635 -0.14  -0.0" rpy="0 0 1.5707963267948966" />
    <parent link="left_gelsight_connector" />
    <child link="left_gelsight_mini" />
    <axis xyz="0 0 1" />
  </joint>

  <joint name="right_gelsight" type="fixed">
    <origin xyz="-0.1635 -0.14  -0.0" rpy="0 0 1.5707963267948966" />
    <parent link="right_gelsight_connector" />
    <child link="right_gelsight_mini" />
    <axis xyz="0 0 1" />
  </joint>

</robot>
